<?xml version="1.0" encoding="utf-8"?>
<!-- This URDF was automatically created by SolidWorks to URDF Exporter! Originally created by Stephen Brawner (brawner@gmail.com) 
     Commit Version: 1.6.0-4-g7f85cfe  Build Version: 1.6.7995.38578
     For more information, please see http://wiki.ros.org/sw_urdf_exporter -->
<robot
  name="so_arm100">
  <link
    name="Base">
    <inertial>
      <origin
        xyz="-2.3054917368973E-06 -0.0176601899267237 0.031113668238176"
        rpy="0 0 0" />
      <mass
        value="0.193749012982645" />
      <inertia
        ixx="0.000137687906786269"
        ixy="-4.28474999585736E-09"
        ixz="2.103221173073E-08"
        iyy="0.00014498981682198"
        iyz="-2.26441221181679E-05"
        izz="0.000168676019768194" />
    </inertial>
    <visual>
      <origin
        xyz="0 0 0"
        rpy="0 0 0" />
      <geometry>
        <mesh
          filename="package://so_arm100/meshes/Base.STL" />
      </geometry>
      <material
        name="">
        <color
          rgba="0.792156862745098 0.819607843137255 0.933333333333333 1" />
      </material>
    </visual>
    <collision>
      <origin
        xyz="0 0 0"
        rpy="0 0 0" />
      <geometry>
        <mesh
          filename="package://so_arm100/meshes/Base.STL" />
      </geometry>
    </collision>
  </link>
  <link
    name="shoulder_link">
    <inertial>
      <origin
        xyz="-9.1232E-05 0.04538 0.031241"
        rpy="0 0 0" />
      <mass
        value="0.11865" />
      <inertia
        ixx="5.9025E-05"
        ixy="4.908E-07"
        ixz="-5.9045E-08"
        iyy="3.2118E-05"
        iyz="-4.5803E-06"
        izz="5.859E-05" />
    </inertial>
    <visual>
      <origin
        xyz="0 0 0"
        rpy="0 0 0" />
      <geometry>
        <mesh
          filename="package://so_arm100/meshes/shoulder_link.STL" />
      </geometry>
      <material
        name="">
        <color
          rgba="0.79216 0.81961 0.93333 1" />
      </material>
    </visual>
    <collision>
      <origin
        xyz="0 0 0"
        rpy="0 0 0" />
      <geometry>
        <mesh
          filename="package://so_arm100/meshes/shoulder_link.STL" />
      </geometry>
    </collision>
  </link>
  <joint
    name="shoulder_pan_joint"
    type="revolute">
    <origin
      xyz="0 -0.0452 0.0305"
      rpy="1.5708 0 0" />
    <parent
      link="Base" />
    <child
      link="shoulder_link" />
    <axis
      xyz="0 -1 0" />
    <limit
      lower="-1.57"
      upper="1.57"
      effort="100"
      velocity="10" />
  </joint>
  <link
    name="upper_arm_link">
    <inertial>
      <origin
        xyz="0.0156827947709601 0.0701802155153415 0.00310545123916983"
        rpy="0 0 0" />
      <mass
        value="0.162409284912556" />
      <inertia
        ixx="0.000167153147342833"
        ixy="1.03902639480366E-06"
        ixz="-1.20158973046588E-08"
        iyy="7.01946994486248E-05"
        iyz="2.11884860629144E-06"
        izz="0.000213280242264327" />
    </inertial>
    <visual>
      <origin
        xyz="0 0 0"
        rpy="0 0 0" />
      <geometry>
        <mesh
          filename="package://so_arm100/meshes/upper_arm_link.STL" />
      </geometry>
      <material
        name="">
        <color
          rgba="0.792156862745098 0.819607843137255 0.933333333333333 1" />
      </material>
    </visual>
    <collision>
      <origin
        xyz="0 0 0"
        rpy="0 0 0" />
      <geometry>
        <mesh
          filename="package://so_arm100/meshes/upper_arm_link.STL" />
      </geometry>
    </collision>
  </link>
  <joint
    name="shoulder_lift_joint"
    type="revolute">
    <origin
      xyz="-0.0158 0.0885 0.0306"
      rpy="0 0 0" />
    <parent
      link="shoulder_link" />
    <child
      link="upper_arm_link" />
    <axis
      xyz="1 0 0" />
    <limit
      lower="-1.57"
      upper="1.57"
      effort="100"
      velocity="10" />
  </joint>
  <link
    name="forearm_link">
    <inertial>
      <origin
        xyz="-0.0193960375787366 0.00137796346147245 0.0768006759493438"
        rpy="0 0 0" />
      <mass
        value="0.147967771056037" />
      <inertia
        ixx="0.000105333994797778"
        ixy="1.73059614958688E-07"
        ixz="-1.17203066998378E-05"
        iyy="0.000138766651583021"
        iyz="1.77429933964553E-06"
        izz="5.08741632405579E-05" />
    </inertial>
    <visual>
      <origin
        xyz="0 0 0"
        rpy="0 0 0" />
      <geometry>
        <mesh
          filename="package://so_arm100/meshes/forearm_link.STL" />
      </geometry>
      <material
        name="">
        <color
          rgba="0.792156862745098 0.819607843137255 0.933333333333333 1" />
      </material>
    </visual>
    <collision>
      <origin
        xyz="0 0 0"
        rpy="0 0 0" />
      <geometry>
        <mesh
          filename="package://so_arm100/meshes/forearm_link.STL" />
      </geometry>
    </collision>
  </link>
  <joint
    name="elbow_joint"
    type="revolute">
    <origin
      xyz="0.0317 0.11257 0.028"
      rpy="0 0 0" />
    <parent
      link="upper_arm_link" />
    <child
      link="forearm_link" />
    <axis
      xyz="1 0 0" />
    <limit
      lower="-1.57"
      upper="1.57"
      effort="100"
      velocity="10" />
  </joint>
  <link
    name="wrist_1_link">
    <inertial>
      <origin
        xyz="-0.0246265312098786 -2.34622216576663E-05 0.0352278998817509"
        rpy="0 0 0" />
      <mass
        value="0.0661320665571636" />
      <inertia
        ixx="1.95717492021957E-05"
        ixy="5.20090676290333E-09"
        ixz="6.62714409160709E-07"
        iyy="3.45401433304967E-05"
        iyz="-4.09549066423119E-08"
        izz="2.38028416973655E-05" />
    </inertial>
    <visual>
      <origin
        xyz="0 0 0"
        rpy="0 0 0" />
      <geometry>
        <mesh
          filename="package://so_arm100/meshes/wrist_1_link.STL" />
      </geometry>
      <material
        name="">
        <color
          rgba="0.792156862745098 0.819607843137255 0.933333333333333 1" />
      </material>
    </visual>
    <collision>
      <origin
        xyz="0 0 0"
        rpy="0 0 0" />
      <geometry>
        <mesh
          filename="package://so_arm100/meshes/wrist_1_link.STL" />
      </geometry>
    </collision>
  </link>
  <joint
    name="wrist_pitch_joint"
    type="revolute">
    <origin
      xyz="0 0.0052 0.1349"
      rpy="0 0 0" />
    <parent
      link="forearm_link" />
    <child
      link="wrist_1_link" />
    <axis
      xyz="1 0 0" />
    <limit
      lower="-1.57"
      upper="1.57"
      effort="100"
      velocity="10" />
  </joint>
  <link
    name="wrist_2_link">
    <inertial>
      <origin
        xyz="0.000450839256531511 -0.00553729747557533 0.0295127613946878"
        rpy="0 0 0" />
      <mass
        value="0.0931646505689508" />
      <inertia
        ixx="5.02748039583909E-05"
        ixy="-5.95959163846009E-07"
        ixz="1.40805138073889E-07"
        iyy="4.34101625280102E-05"
        iyz="7.09851524639004E-06"
        izz="3.04999659322705E-05" />
    </inertial>
    <visual>
      <origin
        xyz="0 0 0"
        rpy="0 0 0" />
      <geometry>
        <mesh
          filename="package://so_arm100/meshes/wrist_2_link.STL" />
      </geometry>
      <material
        name="">
        <color
          rgba="0.792156862745098 0.819607843137255 0.933333333333333 1" />
      </material>
    </visual>
    <collision>
      <origin
        xyz="0 0 0"
        rpy="0 0 0" />
      <geometry>
        <mesh
          filename="package://so_arm100/meshes/wrist_2_link.STL" />
      </geometry>
    </collision>
  </link>
  <joint
    name="wrist_roll_joint"
    type="revolute">
    <origin
      xyz="-0.0161 0 0.0586"
      rpy="0 0 0" />
    <parent
      link="wrist_1_link" />
    <child
      link="wrist_2_link" />
    <axis
      xyz="0 0 -1" />
    <limit
      lower="-1.57"
      upper="1.57"
      effort="100"
      velocity="10" />
  </joint>
  <link
    name="jaw_link">
    <inertial>
      <origin
        xyz="0.015016 0.013795 0.027133"
        rpy="0 0 0" />
      <mass
        value="0.020214" />
      <inertia
        ixx="8.9646E-06"
        ixy="-8.7106E-08"
        ixz="-1.719E-07"
        iyy="9.5035E-06"
        iyz="-3.2096E-06"
        izz="4.5648E-06" />
    </inertial>
    <visual>
      <origin
        xyz="0 0 0"
        rpy="0 0 0" />
      <geometry>
        <mesh
          filename="package://so_arm100/meshes/jaw_link.STL" />
      </geometry>
      <material
        name="">
        <color
          rgba="0.79216 0.81961 0.93333 1" />
      </material>
    </visual>
    <collision>
      <origin
        xyz="0 0 0"
        rpy="0 0 0" />
      <geometry>
        <mesh
          filename="package://so_arm100/meshes/jaw_link.STL" />
      </geometry>
    </collision>
  </link>
  <joint
    name="jaw_joint"
    type="revolute">
    <origin
      xyz="-0.0155 0.0202 0.0259"
      rpy="0 0 0" />
    <parent
      link="wrist_2_link" />
    <child
      link="jaw_link" />
    <axis
      xyz="1 0 0" />
    <limit
      lower="-0.7"
      upper="0.7"
      effort="100"
      velocity="10" />
  </joint>
  <ros2_control name="so_arm100_system" type="system">
    <hardware>
      <plugin>mock_components/GenericSystem</plugin>
    </hardware>
    <joint name="shoulder_pan_joint">
      <command_interface name="position"/>
      <state_interface name="position"/>
      <state_interface name="velocity"/>
    </joint>
    <joint name="shoulder_lift_joint">
      <command_interface name="position"/>
      <state_interface name="position"/>
      <state_interface name="velocity"/>
    </joint>
    <joint name="elbow_joint">
      <command_interface name="position"/>
      <state_interface name="position"/>
      <state_interface name="velocity"/>
    </joint>
    <joint name="wrist_pitch_joint">
      <command_interface name="position"/>
      <state_interface name="position"/>
      <state_interface name="velocity"/>
    </joint>
    <joint name="wrist_roll_joint">
      <command_interface name="position"/>
      <state_interface name="position"/>
      <state_interface name="velocity"/>
    </joint>
    <joint name="jaw_joint">
      <command_interface name="position"/>
      <state_interface name="position"/>
      <state_interface name="velocity"/>
    </joint>
  </ros2_control>
</robot>